Workbook
Name Slicer_Country: #N/A

Sheet Business Questions
B3: 1 | C3: A Quick Analysis of the data
B4: 2 | C4: Information Finder
B5: 3 | C5: Extend Information finder
B6: 4 | C6: Male vs Female Comparision
B7: 5 | C7: Calculate Annual bonus

Sheet NZ Data
C1: Employee Data
C5: Name | D5: Gender | E5: Department | F5: Age | G5: Date Joined | H5: Salary | I5: Rating | J5: Country
C6: Lindy Guillet | D6: Male | E6: Sales | F6: 22 | G6: 44446 | H6: 112780 | I6: Above average | J6: NZ
C7: Ambros Murthwaite | D7: Male | E7: Procurement | F7: 46 | G7: 44758 | H7: 70610 | I7: Average | J7: NZ
C8: Tatum Hush | D8: Female | E8: Sales | F8: 28 | G8: 44357 | H8: 53240 | I8: Average | J8: NZ
C9: Benny Karolovsky | E9: Finance | F9: 37 | G9: 44146 | H9: 115440 | I9: Poor | J9: NZ
C10: Hoyt D'Alesco | D10: Male | E10: Sales | F10: 32 | G10: 44465 | H10: 53540 | I10: Average | J10: NZ
C11: Halimeda Kuscha | D11: Female | E11: Procurement | F11: 30 | G11: 44861 | H11: 112570 | I11: Average | J11: NZ
C12: Erin Androsik | D12: Male | E12: Procurement | F12: 33 | G12: 44701 | H12: 48530 | I12: Above average | J12: NZ
C13: Vic Radolf | D13: Female | E13: Website | F13: 24 | G13: 44148 | H13: 62780 | I13: Average | J13: NZ
C14: William Reeveley | D14: Male | E14: Website | F14: 33 | G14: 44509 | H14: 53870 | I14: Average | J14: NZ
C15: Ewart Laphorn | D15: Female | E15: HR | F15: 27 | G15: 44122 | H15: 119110 | I15: Average | J15: NZ
C16: Bev Lashley | D16: Male | E16: Website | F16: 29 | G16: 44180 | H16: 112110 | I16: Poor | J16: NZ
C17: Kath Bletsoe | D17: Male | E17: Sales | F17: 25 | G17: 44383 | H17: 65700 | I17: Average | J17: NZ
C18: Murry Dryburgh | D18: Male | E18: Website | F18: 37 | G18: 44701 | H18: 69070 | I18: Average | J18: NZ
C19: Kaine Padly | D19: Male | E19: Website | F19: 20 | G19: 44459 | H19: 107700 | I19: Average | J19: NZ
C20: Kassi Jonson | D20: Female | E20: Website | F20: 32 | G20: 44354 | H20: 43840 | I20: Above average | J20: NZ
C21: Simon Kembery | D21: Male | E21: Procurement | F21: 40 | G21: 44263 | H21: 99750 | I21: Average | J21: NZ
... C27: Husein Augar | D27: Female | E27: Finance | F27: 30 | G27: 44389 | H27: 67910 | I27: Poor | J27: NZ
D28: Female | E28: Website | F28: 31 | G28: 44663 | H28: 58100 | I28: Average | J28: NZ
C29: Esmaria Denecamp | D29: Male | E29: Finance | F29: 27 | G29: 44567 | H29: 48980 | I29: Average | J29: NZ
C30: Curtice Advani | E30: Finance | F30: 30 | G30: 44597 | H30: 64000 | I30: Average | J30: NZ
C31: Barr Faughny | D31: Female | E31: Procurement | F31: 42 | G31: 44779 | H31: 75000 | I31: Exceptional | J31: NZ
C32: Merrilee Plenty | D32: Female | E32: Website | F32: 40 | G32: 44337 | H32: 87620 | I32: Average | J32: NZ
C33: Niall Selesnick | D33: Female | E33: Website | F33: 29 | G33: 44023 | H33: 34980 | I33: Average | J33: NZ
C34: Beverie Moffet | D34: Female | E34: Finance | F34: 28 | G34: 44185 | H34: 75970 | I34: Average | J34: NZ
C35: Jehu Rudeforth | D35: Female | E35: Finance | F35: 34 | G35: 44612 | H35: 60130 | I35: Average | J35: NZ
C36: Camilla Castle | D36: Female | E36: Website | F36: 33 | G36: 44374 | H36: 75480 | I36: Very poor | J36: NZ
C37: Roddy Speechley | D37: Male | E37: Procurement | F37: 33 | G37: 44164 | H37: 115920 | I37: Average | J37: NZ
C38: Gray Seamon | D38: Female | E38: Sales | F38: 36 | G38: 44494 | H38: 78540 | I38: Average | J38: NZ
C39: Madelene Upcott | D39: Male | E39: Procurement | F39: 25 | G39: 44726 | H39: 109190 | I39: Above average | J39: NZ
C40: Violante Courtonne | D40: Female | E40: Sales | F40: 34 | G40: 44721 | H40: 49630 | I40: Poor | J40: NZ
C41: Bernie Gorges | D41: Female | E41: Procurement | F41: 28 | G41: 44630 | H41: 99970 | I41: Average | J41: NZ
C42: Torrance Collier | D42: Female | E42: Website | F42: 33 | G42: 44190 | H42: 96140 | I42: Average | J42: NZ
... C67: Wilone O'Kielt | D67: Female | E67: Website | F67: 43 | G67: 45045 | H67: 114870 | I67: Average | J67: NZ
C68: Madge McCloughen | E68: Website | F68: 32 | G68: 44774 | H68: 91310 | I68: Average | J68: NZ
C69: Janene Hairsine | D69: Female | E69: Procurement | F69: 28 | G69: 44486 | H69: 104770 | I69: Average | J69: NZ
C70: Alta Kaszper | D70: Male | E70: Sales | F70: 27 | G70: 44134 | H70: 54970 | I70: Average | J70: NZ
C71: Dennison Crosswaite | E71: Website | F71: 26 | G71: 44271 | H71: 90700 | I71: Above average | J71: NZ
C72: Oran Buxcy | D72: Female | E72: Sales | F72: 38 | G72: 44329 | H72: 56870 | I72: Above average | J72: NZ
...

Sheet Sheet1

Sheet India Staff
B2: Name | C2: Gender | D2: Department | E2: Age | F2: Date Joined | G2: Salary | H2: Rating | I2: Country | K2: Name | L2: Gender | M2: Department | N2: Age | O2: Date Joined | P2: Salary | Q2: Rating | R2: Country
B3: Deepali Charan | C3: Male | D3: Website | E3: 20 | F3: 44122 | G3: 112650 | H3: Average | I3: IND
B4: Yagna Sujeev | C4: Female | D4: Website | E4: 32 | F4: 44293 | G4: 43840 | H4: Above average | I4: IND | K4: Name | L4: Gender | M4: Department | N4: Age | O4: Date Joined | P4: Salary | Q4: Rating | R4: Country
B5: Satyendra Venkatadri | C5: Male | D5: Procurement | E5: 31 | F5: 44663 | G5: 103550 | H5: Average | I5: IND
B6: Madhavdas Buhpathi | C6: Female | D6: HR | E6: 32 | F6: 44339 | G6: 45510 | H6: Average | I6: IND
B7: Sahila Chandrasekhar | D7: Finance | E7: 37 | F7: 44085 | G7: 115440 | H7: Poor | I7: IND
B8: Mirium Seemantini Shivakumar | C8: Female | D8: Sales | E8: 38 | F8: 44268 | G8: 56870 | H8: Above average | I8: IND
B9: Purnendu Vijayarangan | C9: Female | D9: Sales | E9: 25 | F9: 44144 | G9: 92700 | H9: Average | I9: IND
B10: Rukma Vinita | D10: Website | E10: 32 | F10: 44713 | G10: 91310 | H10: Average | I10: IND
B11: Yauvani Tarpa | C11: Male | D11: Sales | E11: 33 | F11: 44324 | G11: 74550 | H11: Average | I11: IND
B12: Damayanti Thangavadivelu | C12: Male | D12: Procurement | E12: 25 | F12: 44665 | G12: 109190 | H12: Above average | I12: IND
B13: Manjusri Ruchi | C13: Female | D13: Website | E13: 40 | F13: 44320 | G13: 104410 | H13: Average | I13: IND
B14: Mithil Nadkarni | C14: Male | D14: Finance | E14: 30 | F14: 44544 | G14: 96800 | H14: Average | I14: IND
B15: Ardhendu Abhichandra Jayakar | C15: Male | D15: Finance | E15: 28 | F15: 43980 | G15: 48170 | H15: Above average | I15: IND
B16: Akbar Sorabhjee | C16: Male | D16: Procurement | E16: 21 | F16: 44042 | G16: 37920 | H16: Average | I16: IND
B17: Bandhula Sathyanna | C17: Male | D17: Procurement | E17: 34 | F17: 44642 | G17: 112650 | H17: Average | I17: IND
B18: Daruka Ghazali | C18: Female | D18: Sales | E18: 34 | F18: 44660 | G18: 49630 | H18: Poor | I18: IND
B19: Heer Pennathur | C19: Male | D19: Website | E19: 36 | F19: 43958 | G19: 118840 | H19: Average | I19: IND
B20: Shekhar Eswara | C20: Male | D20: Website | E20: 30 | F20: 44789 | G20: 69710 | H20: Average | I20: IND
B21: Udyan Lanka | C21: Male | D21: Procurement | E21: 20 | F21: 44683 | G21: 79570 | H21: Average | I21: IND
B22: Shreela Ramasubraman | C22: Female | D22: Procurement | E22: 22 | F22: 44388 | G22: 76900 | H22: Above average | I22: IND
... B53: Indu Varada Sumedh | C53: Female | D53: Finance | E53: 28 | F53: 44124 | G53: 75970 | H53: Average | I53: IND
B54: Karuna Pashupathy | D54: Website | E54: 27 | F54: 44212 | G54: 90700 | H54: Above average | I54: IND
B55: Mardav Ramaswami | C55: Male | D55: Procurement | E55: 30 | F55: 44607 | G55: 60570 | H55: Average | I55: IND
B56: Sarayu Ragunathan | C56: Male | D56: Procurement | E56: 33 | F56: 44103 | G56: 115920 | H56: Average | I56: IND
B57: Kevalkumar Solanki | C57: Female | D57: Finance | E57: 33 | F57: 44006 | G57: 65360 | H57: Average | I57: IND
B58: Upendra Swati | D58: Finance | E58: 30 | F58: 44535 | G58: 64000 | H58: Average | I58: IND
B59: Deepit Ranjana | C59: Female | D59: Finance | E59: 34 | F59: 44383 | G59: 92450 | H59: Average | I59: IND
B60: Amal Nimesh | C60: Male | D60: Website | E60: 31 | F60: 44450 | G60: 48950 | H60: Average | I60: IND
B61: Kunja Prashanta Vibha | C61: Female | D61: Website | E61: 27 | F61: 44625 | G61: 83750 | H61: Average | I61: IND
B62: Godavari Veena | C62: Female | D62: Website | E62: 40 | F62: 44276 | G62: 87620 | H62: Average | I62: IND
B63: Devasree Fullara Saurin | C63: Female | D63: Sales | E63: 20 | F63: 44476 | G63: 68900 | H63: Poor | I63: IND
B64: Geena Raghavanpillai | C64: Male | D64: Sales | E64: 32 | F64: 44403 | G64: 53540 | H64: Average | I64: IND
B65: Rupak Mehra | C65: Male | D65: Sales | E65: 28 | F65: 44758 | G65: 43510 | H65: Very poor | I65: IND
B66: Sawini Chandan | C66: Female | D66: Sales | E66: 38 | F66: 44316 | G66: 109160 | H66: Exceptional | I66: IND
B67: Baruna Ogale | C67: Male | D67: Procurement | E67: 40 | F67: 44204 | G67: 99750 | H67: Average | I67: IND
B68: Jagajeet Viraj | C68: Female | D68: Website | E68: 31 | F68: 44084 | G68: 41980 | H68: Average | I68: IND
B69: Kulbhushan Moorthy | C69: Male | D69: Finance | E69: 36 | F69: 44272 | G69: 71380 | H69: Average | I69: IND
B70: Ilesh Dasgupta | C70: Male | D70: Procurement | E70: 27 | F70: 44547 | G70: 113280 | H70: Very poor | I70: IND
... B98: Madhavdas Buhpathi | C98: Female | D98: HR | E98: 32 | F98: 44339 | G98: 45510 | H98: Average | I98: IND
...

Sheet Total staff
A1: Name | B1: Gender | C1: Department | D1: Age | E1: Date Joined | F1: Salary | G1: Rating | H1: Country | I1: Tenure | J1: Bonus
A2: Deepali Charan | B2: Male | C2: Website | D2: 20 | E2: 44122 | F2: 112650 | G2: Average | H2: IND | I2: =(TODAY()-E2)/365 -> 5.0027397 | J2: =ROUNDUP(IF(I2>3,3%,2%)*F2,0) -> 3380 | L2: <--- 5 | M2: Calculated Annual bonus
A3: Yagna Sujeev | B3: Female | C3: Website | D3: 32 | E3: 44293 | F3: 43840 | G3: Above average | H3: IND | I3: =(TODAY()-E3)/365 -> 4.5342466 | J3: =ROUNDUP(IF(I3>3,3%,2%)*F3,0) -> 1316
A4: Satyendra Venkatadri | B4: Male | C4: Procurement | D4: 31 | E4: 44663 | F4: 103550 | G4: Average | H4: IND | I4: =(TODAY()-E4)/365 -> 3.5205479 | J4: =ROUNDUP(IF(I4>3,3%,2%)*F4,0) -> 3107
A5: Madhavdas Buhpathi | B5: Female | C5: HR | D5: 32 | E5: 44339 | F5: 45510 | G5: Average | H5: IND | I5: =(TODAY()-E5)/365 -> 4.4082192 | J5: =ROUNDUP(IF(I5>3,3%,2%)*F5,0) -> 1366
A6: Sahila Chandrasekhar | B6: Not found | C6: Finance | D6: 37 | E6: 44085 | F6: 115440 | G6: Poor | H6: IND | I6: =(TODAY()-E6)/365 -> 5.1041096 | J6: =ROUNDUP(IF(I6>3,3%,2%)*F6,0) -> 3464
A7: Mirium Seemantini Shivakumar | B7: Female | C7: Sales | D7: 38 | E7: 44268 | F7: 56870 | G7: Above average | H7: IND | I7: =(TODAY()-E7)/365 -> 4.6027397 | J7: =ROUNDUP(IF(I7>3,3%,2%)*F7,0) -> 1707
A8: Purnendu Vijayarangan | B8: Female | C8: Sales | D8: 25 | E8: 44144 | F8: 92700 | G8: Average | H8: IND | I8: =(TODAY()-E8)/365 -> 4.9424658 | J8: =ROUNDUP(IF(I8>3,3%,2%)*F8,0) -> 2781
A9: Rukma Vinita | B9: Not found | C9: Website | D9: 32 | E9: 44713 | F9: 91310 | G9: Average | H9: IND | I9: =(TODAY()-E9)/365 -> 3.3835616 | J9: =ROUNDUP(IF(I9>3,3%,2%)*F9,0) -> 2740
A10: Yauvani Tarpa | B10: Male | C10: Sales | D10: 33 | E10: 44324 | F10: 74550 | G10: Average | H10: IND | I10: =(TODAY()-E10)/365 -> 4.4493151 | J10: =ROUNDUP(IF(I10>3,3%,2%)*F10,0) -> 2237
A11: Damayanti Thangavadivelu | B11: Male | C11: Procurement | D11: 25 | E11: 44665 | F11: 109190 | G11: Above average | H11: IND | I11: =(TODAY()-E11)/365 -> 3.5150685 | J11: =ROUNDUP(IF(I11>3,3%,2%)*F11,0) -> 3276
A12: Manjusri Ruchi | B12: Female | C12: Website | D12: 40 | E12: 44320 | F12: 104410 | G12: Average | H12: IND | I12: =(TODAY()-E12)/365 -> 4.460274 | J12: =ROUNDUP(IF(I12>3,3%,2%)*F12,0) -> 3133
A13: Mithil Nadkarni | B13: Male | C13: Finance | D13: 30 | E13: 44544 | F13: 96800 | G13: Average | H13: IND | I13: =(TODAY()-E13)/365 -> 3.8465753 | J13: =ROUNDUP(IF(I13>3,3%,2%)*F13,0) -> 2904
A14: Ardhendu Abhichandra Jayakar | B14: Male | C14: Finance | D14: 28 | E14: 43980 | F14: 48170 | G14: Above average | H14: IND | I14: =(TODAY()-E14)/365 -> 5.3917808 | J14: =ROUNDUP(IF(I14>3,3%,2%)*F14,0) -> 1446
... A184: Zach Polon | B184: Male | C184: Procurement | D184: 26 | E184: 44411 | F184: 53540 | G184: Average | H184: NZ | I184: =(TODAY()-E184)/365 -> 4.2109589 | J184: =ROUNDUP(IF(I184>3,3%,2%)*F184,0) -> 1607

Sheet Analysis
A1: 1 | B1: A Quick Analysis of the data
A2: Count of employees | B2: =COUNTA('Total staff'!A2:A184) -> 183
A3: Average salary | B3: {=AVERAGE('Total staff'!F2:F184)} -> 77173.716
A4: Average Age | B4: {=AVERAGE('Total staff'!D2:D184)} -> 30.42623
A5: Average Tenure | B5: =AVERAGE('Total staff'!I2:I184) -> 4.1505951
A6: Female count | B6: =COUNTIF('Total staff'!B2:B184,"Female") -> 86
A7: Female ratio% | B7: =B6/B2 -> 0.46994536
A8: Mid value of salary | B8: =MEDIAN('Total staff'!F2:F184) -> 75000
A9: Mid value of Age | B9: =MEDIAN('Total staff'!D2:D184) -> 30
A10: salary above $90K | B10: =COUNTIF('Total staff'!F2:F184,">=90000") -> 63
A13: 2 | B13: Information Finder
B15: Shekhar Eswara
A16: Vlookup | B16: {=VLOOKUP(B15,'Total staff'!A1:I184,{2,3,4,5,6,7,8,9},FALSE)} -> Male | C16: Website | D16: 30 | E16: 44789 | F16: 69710 | G16: Average | H16: IND | I16: 2.7068493
B18: 44665
A19: Xlookup | B19: =_xlfn.XLOOKUP(B18,'Total staff'!E2:E184,'Total staff'!A2:A184) -> Damayanti Thangavadivelu
A22: 3 | B22: Extend Information finder
A25: Dept | B25: sales | D25: Getting only sales persons name, age, salary and rating in decsending order
A26: No of sales person: | B26: =COUNTIF('Total staff'!C2:C184,B25) -> 28
A27: 1 | B27: 2 | C27: 3 | D27: 4 | E27: 5 | F27: 6 | G27: 7 | H27: 8 | I27: 9
A28: {=_xlfn._xlws.SORT(_xlfn.CHOOSECOLS(_xlfn._xlws.FILTER('Total staff'!A2:I184,'Total staff'!C2:C184=B25,"No match found"),1,4,5,7),3,-1)} -> #NAME? | B28: 28 | C28: 44820 | D28: Very poor
A29: Rupak Mehra | B29: 28 | C29: 44758 | D29: Very poor
A30: Violante Courtonne | B30: 34 | C30: 44721 | D30: Poor
A31: Daruka Ghazali | B31: 34 | C31: 44660 | D31: Poor
A32: Bili Sizey | B32: 43 | C32: 44620 | D32: Average
A33: Waheeda Vasuman | B33: 43 | C33: 44558 | D33: Average
A34: Hyacinthie Braybrooke | B34: 20 | C34: 44537 | D34: Poor
A35: Gray Seamon | B35: 36 | C35: 44494 | D35: Average
A36: Devasree Fullara Saurin | B36: 20 | C36: 44476 | D36: Poor
A37: Hoyt D'Alesco | B37: 32 | C37: 44465 | D37: Average
A38: Lindy Guillet | B38: 22 | C38: 44446 | D38: Above average
A39: Shulabh Qutub Sundaramoorthy | B39: 36 | C39: 44433 | D39: Average
A40: Geena Raghavanpillai | B40: 32 | C40: 44403 | D40: Average
... A55: Sanchali Shirish | B55: 27 | C55: 44073 | D55: Average

Sheet Male vs Female Comparision
A2: 4 | B2: Gender comparison
D6: Gender
C7: Values | D7: Female | E7: Male
C8: Count of Name | D8: 43 | E8: 44
C9: Average of Age | D9: 31.395349 | E9: 29.340909
C10: Average of Salary | D10: 78284.186 | E10: 74486.364
C11: Average of Tenure | D11: 3.5410003 | E11: 3.5380448

Sheet data Visualization
A1: 1 | B1: Analyze salary Spread
A2: 2 | B2: Any Correlation between salary and rating
A3: 3 | B3: Company growth over time
A4: 4 | B4: Regional scorecard | Q4: Analyze salary Spread
A8: Name | B8: Gender | C8: Department | D8: Age | E8: Date Joined | F8: Salary | G8: Rating | H8: Country | I8: Tenure | J8: Bonus | K8: Rating as number | L8: Year
A9: Shubhra Potla | B9: Female | C9: Website | D9: 21 | E9: 44619 | F9: 33920 | G9: Average | H9: IND | I9: =(TODAY()-E9)/365 -> 3.6410959 | J9: =ROUNDUP(IF(I9>3,3%,2%)*F9,0) -> 1018 | K9: =_xlfn.XLOOKUP(G9,$R$36:$R$40,$T$36:$T$40) -> 3 | L9: =YEAR(E9) -> 2022
A10: Gretchen Callow | B10: Female | C10: Website | D10: 21 | E10: 44678 | F10: 33920 | G10: Average | H10: NZ | I10: =(TODAY()-E10)/365 -> 3.4794521 | J10: =ROUNDUP(IF(I10>3,3%,2%)*F10,0) -> 1018 | K10: =_xlfn.XLOOKUP(G10,$R$36:$R$40,$T$36:$T$40) -> 3 | L10: =YEAR(E10) -> 2022
A11: Suchira Bhanupriya Tapti | B11: Female | C11: Website | D11: 29 | E11: 43962 | F11: 34980 | G11: Average | H11: IND | I11: =(TODAY()-E11)/365 -> 5.4410959 | J11: =ROUNDUP(IF(I11>3,3%,2%)*F11,0) -> 1050 | K11: =_xlfn.XLOOKUP(G11,$R$36:$R$40,$T$36:$T$40) -> 3 | L11: =YEAR(E11) -> 2020
A12: Niall Selesnick | B12: Female | C12: Website | D12: 29 | E12: 44023 | F12: 34980 | G12: Average | H12: NZ | I12: =(TODAY()-E12)/365 -> 5.2739726 | J12: =ROUNDUP(IF(I12>3,3%,2%)*F12,0) -> 1050 | K12: =_xlfn.XLOOKUP(G12,$R$36:$R$40,$T$36:$T$40) -> 3 | L12: =YEAR(E12) -> 2020
A13: Waheeda Vasuman | B13: Male | C13: Sales | D13: 43 | E13: 44558 | F13: 36040 | G13: Average | H13: IND | I13: =(TODAY()-E13)/365 -> 3.8082192 | J13: =ROUNDUP(IF(I13>3,3%,2%)*F13,0) -> 1082 | K13: =_xlfn.XLOOKUP(G13,$R$36:$R$40,$T$36:$T$40) -> 3 | L13: =YEAR(E13) -> 2021
A14: Bili Sizey | B14: Male | C14: Sales | D14: 43 | E14: 44620 | F14: 36040 | G14: Average | H14: NZ | I14: =(TODAY()-E14)/365 -> 3.6383562 | J14: =ROUNDUP(IF(I14>3,3%,2%)*F14,0) -> 1082 | K14: =_xlfn.XLOOKUP(G14,$R$36:$R$40,$T$36:$T$40) -> 3 | L14: =YEAR(E14) -> 2022
A15: Akbar Sorabhjee | B15: Male | C15: Procurement | D15: 21 | E15: 44042 | F15: 37920 | G15: Average | H15: IND | I15: =(TODAY()-E15)/365 -> 5.2219178 | J15: =ROUNDUP(IF(I15>3,3%,2%)*F15,0) -> 1138 | K15: =_xlfn.XLOOKUP(G15,$R$36:$R$40,$T$36:$T$40) -> 3 | L15: =YEAR(E15) -> 2020
A16: Orton Livick | B16: Male | C16: Procurement | D16: 21 | E16: 44104 | F16: 37920 | G16: Average | H16: NZ | I16: =(TODAY()-E16)/365 -> 5.0520548 | J16: =ROUNDUP(IF(I16>3,3%,2%)*F16,0) -> 1138 | K16: =_xlfn.XLOOKUP(G16,$R$36:$R$40,$T$36:$T$40) -> 3 | L16: =YEAR(E16) -> 2020
A17: Shobhana Samuel | B17: Male | C17: Procurement | D17: 35 | E17: 44666 | F17: 40400 | G17: Average | H17: IND | I17: =(TODAY()-E17)/365 -> 3.5123288 | J17: =ROUNDUP(IF(I17>3,3%,2%)*F17,0) -> 1212 | K17: =_xlfn.XLOOKUP(G17,$R$36:$R$40,$T$36:$T$40) -> 3 | L17: =YEAR(E17) -> 2022
A18: Archibald Filliskirk | B18: Male | C18: Procurement | D18: 35 | E18: 44727 | F18: 40400 | G18: Average | H18: NZ | I18: =(TODAY()-E18)/365 -> 3.3452055 | J18: =ROUNDUP(IF(I18>3,3%,2%)*F18,0) -> 1212 | K18: =_xlfn.XLOOKUP(G18,$R$36:$R$40,$T$36:$T$40) -> 3 | L18: =YEAR(E18) -> 2022
A19: Prerana Nishita | B19: Female | C19: Procurement | D19: 32 | E19: 44549 | F19: 41570 | G19: Average | H19: IND | I19: =(TODAY()-E19)/365 -> 3.8328767 | J19: =ROUNDUP(IF(I19>3,3%,2%)*F19,0) -> 1248 | K19: =_xlfn.XLOOKUP(G19,$R$36:$R$40,$T$36:$T$40) -> 3 | L19: =YEAR(E19) -> 2021
A20: Crissie Cordel | B20: Female | C20: Procurement | D20: 32 | E20: 44611 | F20: 41570 | G20: Average | H20: NZ | I20: =(TODAY()-E20)/365 -> 3.6630137 | J20: =ROUNDUP(IF(I20>3,3%,2%)*F20,0) -> 1248 | K20: =_xlfn.XLOOKUP(G20,$R$36:$R$40,$T$36:$T$40) -> 3 | L20: =YEAR(E20) -> 2022
... A32: Jan Morforth | B32: Male | C32: Finance | D32: 28 | E32: 44041 | F32: 48170 | G32: Above average | H32: NZ | I32: =(TODAY()-E32)/365 -> 5.2246575 | J32: =ROUNDUP(IF(I32>3,3%,2%)*F32,0) -> 1446 | K32: =_xlfn.XLOOKUP(G32,$R$36:$R$40,$T$36:$T$40) -> 4 | L32: =YEAR(E32) -> 2020
A33: Piyali Mahanthapa | B33: Male | C33: Procurement | D33: 33 | E33: 44640 | F33: 48530 | G33: Above average | H33: IND | I33: =(TODAY()-E33)/365 -> 3.5835616 | J33: =ROUNDUP(IF(I33>3,3%,2%)*F33,0) -> 1456 | K33: =_xlfn.XLOOKUP(G33,$R$36:$R$40,$T$36:$T$40) -> 4 | L33: =YEAR(E33) -> 2022 | P33: Any Correlation between salary and rating
A34: Erin Androsik | B34: Male | C34: Procurement | D34: 33 | E34: 44701 | F34: 48530 | G34: Above average | H34: NZ | I34: =(TODAY()-E34)/365 -> 3.4164384 | J34: =ROUNDUP(IF(I34>3,3%,2%)*F34,0) -> 1456 | K34: =_xlfn.XLOOKUP(G34,$R$36:$R$40,$T$36:$T$40) -> 4 | L34: =YEAR(E34) -> 2022
A35: Amal Nimesh | B35: Male | C35: Website | D35: 31 | E35: 44450 | F35: 48950 | G35: Average | H35: IND | I35: =(TODAY()-E35)/365 -> 4.1041096 | J35: =ROUNDUP(IF(I35>3,3%,2%)*F35,0) -> 1469 | K35: =_xlfn.XLOOKUP(G35,$R$36:$R$40,$T$36:$T$40) -> 3 | L35: =YEAR(E35) -> 2021
A36: Gunar Cockshoot | B36: Male | C36: Website | D36: 31 | E36: 44511 | F36: 48950 | G36: Average | H36: NZ | I36: =(TODAY()-E36)/365 -> 3.9369863 | J36: =ROUNDUP(IF(I36>3,3%,2%)*F36,0) -> 1469 | K36: =_xlfn.XLOOKUP(G36,$R$36:$R$40,$T$36:$T$40) -> 3 | L36: =YEAR(E36) -> 2021 | N36: Rating | O36: Count of Name | P36: Average of Salary | R36: Exceptional | T36: 5
A37: Vanmala Shriharsha | B37: Male | C37: Finance | D37: 27 | E37: 44506 | F37: 48980 | G37: Average | H37: IND | I37: =(TODAY()-E37)/365 -> 3.9506849 | J37: =ROUNDUP(IF(I37>3,3%,2%)*F37,0) -> 1470 | K37: =_xlfn.XLOOKUP(G37,$R$36:$R$40,$T$36:$T$40) -> 3 | L37: =YEAR(E37) -> 2021 | N37: Exceptional | O37: 4 | P37: 92080 | R37: Above average | T37: 4
A38: Esmaria Denecamp | B38: Male | C38: Finance | D38: 27 | E38: 44567 | F38: 48980 | G38: Average | H38: NZ | I38: =(TODAY()-E38)/365 -> 3.7835616 | J38: =ROUNDUP(IF(I38>3,3%,2%)*F38,0) -> 1470 | K38: =_xlfn.XLOOKUP(G38,$R$36:$R$40,$T$36:$T$40) -> 3 | L38: =YEAR(E38) -> 2022 | N38: Above average | O38: 20 | P38: 75933 | R38: Average | T38: 3
A39: Daruka Ghazali | B39: Female | C39: Sales | D39: 34 | E39: 44660 | F39: 49630 | G39: Poor | H39: IND | I39: =(TODAY()-E39)/365 -> 3.5287671 | J39: =ROUNDUP(IF(I39>3,3%,2%)*F39,0) -> 1489 | K39: =_xlfn.XLOOKUP(G39,$R$36:$R$40,$T$36:$T$40) -> 2 | L39: =YEAR(E39) -> 2022 | N39: Average | O39: 137 | P39: 76798.759 | R39: Poor | T39: 2
A40: Violante Courtonne | B40: Female | C40: Sales | D40: 34 | E40: 44721 | F40: 49630 | G40: Poor | H40: NZ | I40: =(TODAY()-E40)/365 -> 3.3616438 | J40: =ROUNDUP(IF(I40>3,3%,2%)*F40,0) -> 1489 | K40: =_xlfn.XLOOKUP(G40,$R$36:$R$40,$T$36:$T$40) -> 2 | L40: =YEAR(E40) -> 2022 | N40: Poor | O40: 16 | P40: 78115 | R40: Very poor | T40: 1
A41: Gumwant Veera | B41: Male | C41: Finance | D41: 24 | E41: 44375 | F41: 52610 | G41: Poor | H41: IND | I41: =(TODAY()-E41)/365 -> 4.309589 | J41: =ROUNDUP(IF(I41>3,3%,2%)*F41,0) -> 1579 | K41: =_xlfn.XLOOKUP(G41,$R$36:$R$40,$T$36:$T$40) -> 2 | L41: =YEAR(E41) -> 2021 | N41: Very poor | O41: 6 | P41: 77423.333
A42: Kaye Crocroft | B42: Male | C42: Finance | D42: 24 | E42: 44436 | F42: 52610 | G42: Poor | H42: NZ | I42: =(TODAY()-E42)/365 -> 4.1424658 | J42: =ROUNDUP(IF(I42>3,3%,2%)*F42,0) -> 1579 | K42: =_xlfn.XLOOKUP(G42,$R$36:$R$40,$T$36:$T$40) -> 2 | L42: =YEAR(E42) -> 2021 | N42: Grand Total | O42: 183 | P42: 77173.716
A43: Anumati Shyamari Meherhomji | B43: Female | C43: Sales | D43: 28 | E43: 44296 | F43: 53240 | G43: Average | H43: IND | I43: =(TODAY()-E43)/365 -> 4.5260274 | J43: =ROUNDUP(IF(I43>3,3%,2%)*F43,0) -> 1598 | K43: =_xlfn.XLOOKUP(G43,$R$36:$R$40,$T$36:$T$40) -> 3 | L43: =YEAR(E43) -> 2021
A44: Tatum Hush | B44: Female | C44: Sales | D44: 28 | E44: 44357 | F44: 53240 | G44: Average | H44: NZ | I44: =(TODAY()-E44)/365 -> 4.3589041 | J44: =ROUNDUP(IF(I44>3,3%,2%)*F44,0) -> 1598 | K44: =_xlfn.XLOOKUP(G44,$R$36:$R$40,$T$36:$T$40) -> 3 | L44: =YEAR(E44) -> 2021
A45: Geena Raghavanpillai | B45: Male | C45: Sales | D45: 32 | E45: 44403 | F45: 53540 | G45: Average | H45: IND | I45: =(TODAY()-E45)/365 -> 4.2328767 | J45: =ROUNDUP(IF(I45>3,3%,2%)*F45,0) -> 1607 | K45: =_xlfn.XLOOKUP(G45,$R$36:$R$40,$T$36:$T$40) -> 3 | L45: =YEAR(E45) -> 2021
A46: Chitrasen Laul | B46: Male | C46: Procurement | D46: 26 | E46: 44350 | F46: 53540 | G46: Average | H46: IND | I46: =(TODAY()-E46)/365 -> 4.3780822 | J46: =ROUNDUP(IF(I46>3,3%,2%)*F46,0) -> 1607 | K46: =_xlfn.XLOOKUP(G46,$R$36:$R$40,$T$36:$T$40) -> 3 | L46: =YEAR(E46) -> 2021
A47: Hoyt D'Alesco | B47: Male | C47: Sales | D47: 32 | E47: 44465 | F47: 53540 | G47: Average | H47: NZ | I47: =(TODAY()-E47)/365 -> 4.0630137 | J47: =ROUNDUP(IF(I47>3,3%,2%)*F47,0) -> 1607 | K47: =_xlfn.XLOOKUP(G47,$R$36:$R$40,$T$36:$T$40) -> 3 | L47: =YEAR(E47) -> 2021
A48: Zach Polon | B48: Male | C48: Procurement | D48: 26 | E48: 44411 | F48: 53540 | G48: Average | H48: NZ | I48: =(TODAY()-E48)/365 -> 4.2109589 | J48: =ROUNDUP(IF(I48>3,3%,2%)*F48,0) -> 1607 | K48: =_xlfn.XLOOKUP(G48,$R$36:$R$40,$T$36:$T$40) -> 3 | L48: =YEAR(E48) -> 2021
A49: Pragya Nilufar | B49: Male | C49: Website | D49: 33 | E49: 44448 | F49: 53870 | G49: Average | H49: IND | I49: =(TODAY()-E49)/365 -> 4.109589 | J49: =ROUNDUP(IF(I49>3,3%,2%)*F49,0) -> 1617 | K49: =_xlfn.XLOOKUP(G49,$R$36:$R$40,$T$36:$T$40) -> 3 | L49: =YEAR(E49) -> 2021
A50: William Reeveley | B50: Male | C50: Website | D50: 33 | E50: 44509 | F50: 53870 | G50: Average | H50: NZ | I50: =(TODAY()-E50)/365 -> 3.9424658 | J50: =ROUNDUP(IF(I50>3,3%,2%)*F50,0) -> 1617 | K50: =_xlfn.XLOOKUP(G50,$R$36:$R$40,$T$36:$T$40) -> 3 | L50: =YEAR(E50) -> 2021
A51: Sanchali Shirish | B51: Male | C51: Sales | D51: 27 | E51: 44073 | F51: 54970 | G51: Average | H51: IND | I51: =(TODAY()-E51)/365 -> 5.1369863 | J51: =ROUNDUP(IF(I51>3,3%,2%)*F51,0) -> 1650 | K51: =_xlfn.XLOOKUP(G51,$R$36:$R$40,$T$36:$T$40) -> 3 | L51: =YEAR(E51) -> 2020
A52: Alta Kaszper | B52: Male | C52: Sales | D52: 27 | E52: 44134 | F52: 54970 | G52: Average | H52: NZ | I52: =(TODAY()-E52)/365 -> 4.969863 | J52: =ROUNDUP(IF(I52>3,3%,2%)*F52,0) -> 1650 | K52: =_xlfn.XLOOKUP(G52,$R$36:$R$40,$T$36:$T$40) -> 3 | L52: =YEAR(E52) -> 2020
A53: Mirium Seemantini Shivakumar | B53: Female | C53: Sales | D53: 38 | E53: 44268 | F53: 56870 | G53: Above average | H53: IND | I53: =(TODAY()-E53)/365 -> 4.6027397 | J53: =ROUNDUP(IF(I53>3,3%,2%)*F53,0) -> 1707 | K53: =_xlfn.XLOOKUP(G53,$R$36:$R$40,$T$36:$T$40) -> 4 | L53: =YEAR(E53) -> 2021
A54: Oran Buxcy | B54: Female | C54: Sales | D54: 38 | E54: 44329 | F54: 56870 | G54: Above average | H54: NZ | I54: =(TODAY()-E54)/365 -> 4.4356164 | J54: =ROUNDUP(IF(I54>3,3%,2%)*F54,0) -> 1707 | K54: =_xlfn.XLOOKUP(G54,$R$36:$R$40,$T$36:$T$40) -> 4 | L54: =YEAR(E54) -> 2021
...
